Workbook
Name Slicer_Discount_Category: #N/A
Name Slicer_Rating_Category: #N/A

Sheet Excel_jumia
A1: Product | B1: Current price | C1: old price | D1: Discount | E1: Review | F1: Ratingd
A2: 115 Piece Set Of Multifunctional Precision Screwdrivers | B2: KSh 950 | C2: KSh 1,525 | D2: 0.38 | E2: -2 | F2: 4.5 out of 5
A3: Metal Decorative Hooks Key Hangers Entryway Wall Hooks Towel Hooks - Home | B3: KSh 527 | C3: KSh 999 | D3: 0.47 | E3: -14 | F3: 4.1 out of 5
A4: Portable Mini Cordless Car Vacuum Cleaner - Blue | B4: KSh 2,199 | C4: KSh 2,923 | D4: 0.25 | E4: -24 | F4: 4.6 out of 5
A5: Weighing Scale Digital Bathroom Body Fat Scale USB-Black | B5: KSh 1,580 | C5: KSh 2,499 | D5: 0.37 | E5: -7 | F5: 4.7 out of 5
A6: Portable Home Small Air Humidifier 3-Speed Fan - Green | B6: KSh 1,740 | C6: KSh 2,356 | D6: 0.26 | E6: -5 | F6: 4.8 out of 5
A7: 220V 60W Electric Soldering Iron Kits With Tools, Tips, And Multimeter | B7: KSh 2,999 | C7: KSh 3,290 | D7: 0.09 | E7: -15 | F7: 4 out of 5
A8: 137 Pieces Cake Decorating Tool Set Baking Supplies | B8: KSh 2,319 | C8: KSh 3,032 | D8: 0.24 | E8: -55 | F8: 4.6 out of 5
A9: Desk Foldable Fan Adjustable Fan Strong Wind 3 Gear Usb | B9: KSh 988 | C9: KSh 1,580 | D9: 0.37 | E9: -2 | F9: 4 out of 5
A10: LASA FOLDING TABLE SERVING STAND | B10: KSh 1,274 | C10: KSh 2,800 | D10: 0.55 | E10: -5 | F10: 4.8 out of 5
A11: 13 In 1 Home Repair Tools Box Kit Set | B11: KSh 1,600 | C11: KSh 2,929 | D11: 0.45 | E11: -5 | F11: 3.8 out of 5
A12: Genebre 115 In 1 Screwdriver Repairing Tool Set For IPhone Cellphone Hand Tool | B12: KSh 799 | C12: KSh 999 | D12: 0.2 | E12: -12 | F12: 4.1 out of 5
A13: 100 Pcs Crochet Hook Tool Set Knitting Hook Set With Box | B13: KSh 990 | C13: KSh 1,500 | D13: 0.34 | E13: -39 | F13: 4.7 out of 5
... A22: 3PCS Single Head Knitting Crochet Sweater Needle Set | B22: KSh 38 | C22: KSh 80 | D22: 0.53 | E22: -13 | F22: 3.3 out of 5
A23: 4pcs Bathroom/Kitchen Towel Rack,Roll Paper Holder,Towel Bars,Hook | B23: KSh 1,860 | C23: KSh 3,220 | D23: 0.42
A24: LED Romantic Spaceship Starry Sky Projector,Children's Bedroom Night Light-Blue | B24: KSh 880 | C24: KSh 1,350 | D24: 0.35 | E24: -6 | F24: 4 out of 5
A25: Foldable Overbed Table/Desk | B25: KSh 1,650 | C25: KSh 2,150 | D25: 0.23 | E25: -14 | F25: 4.4 out of 5
A26: LASA 3 Tier Bamboo Shoe Bench Storage Shelf | B26: KSh 2,048 | C26: KSh 4,500 | D26: 0.54 | E26: -7 | F26: 4.3 out of 5
A27: Electronic Digital Display Vernier Caliper | B27: KSh 420 | C27: KSh 647 | D27: 0.35 | E27: -49 | F27: 4.6 out of 5
A28: Portable Wardrobe Nonwoven With 3 Hanging Rods And 6 Storage Shelves | B28: KSh 2,880 | C28: KSh 3,520 | D28: 0.18 | E28: -12 | F28: 3.8 out of 5
A29: 12 Litre Black Insulated Lunch Box | B29: KSh 1,350 | C29: KSh 1,990 | D29: 0.32 | E29: -13 | F29: 3.8 out of 5
A30: 52 Pieces Cake Decorating Tool Set Gift Kit Baking Supplies | B30: KSh 1,758 | C30: KSh 2,499 | D30: 0.3 | E30: -20 | F30: 4.1 out of 5
A31: MultiFunctional Storage Rack Multi-layer Bookshelf | B31: KSh 2,200 | C31: KSh 4,080 | D31: 0.46
A32: Exfoliate And Exfoliate Face Towel - Black | B32: KSh 185 | C32: KSh 382 | D32: 0.52 | E32: -9 | F32: 4.3 out of 5
A33: 12 Litre Insulated Lunch Box Grey | B33: KSh 980 | C33: KSh 1,490 | D33: 0.34 | E33: -12 | F33: 4.7 out of 5
A34: LED Eye Protection Desk Lamp , Study, Reading, USB Fan - Double Pen Holder | B34: KSh 1,820 | C34: KSh 3,490 | D34: 0.48 | E34: -9 | F34: 4.3 out of 5
A35: 53Pcs/Set Yarn Knitting Crochet Hooks With Bag - Fortune Cat | B35: KSh 1,940 | C35: KSh 2,650 | D35: 0.27 | E35: -20 | F35: 4.7 out of 5
A36: 53 Pieces/Set Yarn Knitting Crochet Hooks With Bag - Pansies | B36: KSh 1,980 | C36: KSh 2,699 | D36: 0.27 | E36: -32 | F36: 4.5 out of 5
A37: DIY File Folder, Office Drawer File Holder, Pen Holder, Desktop Storage Rack | B37: KSh 1,620 | C37: KSh 2,690 | D37: 0.4 | E37: -1 | F37: 5 out of 5
A38: Classic Black Cat Cotton Hemp Pillow Case For Home Car | B38: KSh 171 | C38: KSh 360 | D38: 0.53 | E38: -2 | F38: 5 out of 5
A39: Punch-free Great Load Bearing Bathroom Storage Rack Wall Shelf-White | B39: KSh 389 | C39: KSh 656 | D39: 0.41 | E39: -36 | F39: 4.3 out of 5
A40: 1/2/3 Seater Elastic Sofa Cover,Living Room/Home Decor Chair Cover-Grey | B40: KSh 1,620 - KSh 1,980 | C40: KSh 2,200 - KSh 3,200 | D40: 0.38 | E40: -2 | F40: 4.5 out of 5
A41: LASA Stainless Steel Double Wall Mount Soap Dispenser - 500ml | B41: KSh 2,750 | C41: KSh 4,471 | D41: 0.38
A42: 4M Float Switch Water Level Controller -Water Tank | B42: KSh 475 | C42: KSh 931 | D42: 0.49
A43: Modern Sofa Throw Pillow Cover-45x45cm-Blue&Red | B43: KSh 238 | C43: KSh 476 | D43: 0.5
A44: Balloon Insert, Birthday Party Balloon Set, PU Leather | B44: KSh 610 | C44: KSh 1,060 | D44: 0.42
A45: Balloon Insert, Birthday Party Balloon Set, PU Leather | B45: KSh 610 | C45: KSh 1,060 | D45: 0.42
A46: Shower Cap Wide Elastic Band Cover Reusable Bashroom Cap | B46: KSh 2,132 | C46: KSh 2,169 | D46: 0.02
A47: Christmas Elk Fence Yard Lawn Decorations Cute For Holidays | B47: KSh 999 | C47: KSh 2,000 | D47: 0.5
A48: 60W Hot Melt Glue Sprayer - Efficient And Stable Glue Dispensing | B48: KSh 1,190 | C48: KSh 1,785 | D48: 0.33
...

Sheet Staging_Data
A1: Product | B1: Current price | C1: Old price | D1: Discount Amount | E1: Discount | F1: Discount Category | G1: Review | H1: Rating | I1: Rating Category
A2: 115 Piece Set Of Multifunctional Precision Screwdrivers | B2: 950 | C2: 1525 | D2: =C2-B2 -> 575 | E2: 0.38 | F2: =IF(E2<20%,"Low",IF(E2>40%,"High","Medium")) -> Medium | G2: 2 | H2: 4.5 | I2: =IF(H2<3,"Poor",IF(H2>=4.5,"Excellent","Average")) -> Excellent
A3: Metal Decorative Hooks Key Hangers Entryway Wall Hooks Towel Hooks - Home | B3: 527 | C3: 999 | D3: =C3-B3 -> 472 | E3: 0.47 | F3: =IF(E3<20%,"Low",IF(E3>40%,"High","Medium")) -> High | G3: 14 | H3: 4.1 | I3: =IF(H3<3,"Poor",IF(H3>=4.5,"Excellent","Average")) -> Average
A4: Portable Mini Cordless Car Vacuum Cleaner - Blue | B4: 2199 | C4: 2923 | D4: =C4-B4 -> 724 | E4: 0.25 | F4: =IF(E4<20%,"Low",IF(E4>40%,"High","Medium")) -> Medium | G4: 24 | H4: 4.6 | I4: =IF(H4<3,"Poor",IF(H4>=4.5,"Excellent","Average")) -> Excellent
A5: Weighing Scale Digital Bathroom Body Fat Scale USB-Black | B5: 1580 | C5: 2499 | D5: =C5-B5 -> 919 | E5: 0.37 | F5: =IF(E5<20%,"Low",IF(E5>40%,"High","Medium")) -> Medium | G5: 7 | H5: 4.7 | I5: =IF(H5<3,"Poor",IF(H5>=4.5,"Excellent","Average")) -> Excellent
A6: Portable Home Small Air Humidifier 3-Speed Fan - Green | B6: 1740 | C6: 2356 | D6: =C6-B6 -> 616 | E6: 0.26 | F6: =IF(E6<20%,"Low",IF(E6>40%,"High","Medium")) -> Medium | G6: 5 | H6: 4.8 | I6: =IF(H6<3,"Poor",IF(H6>=4.5,"Excellent","Average")) -> Excellent
A7: 220V 60W Electric Soldering Iron Kits With Tools, Tips, And Multimeter | B7: 2999 | C7: 3290 | D7: =C7-B7 -> 291 | E7: 0.09 | F7: =IF(E7<20%,"Low",IF(E7>40%,"High","Medium")) -> Low | G7: 15 | H7: 4 | I7: =IF(H7<3,"Poor",IF(H7>=4.5,"Excellent","Average")) -> Average
A8: 137 Pieces Cake Decorating Tool Set Baking Supplies | B8: 2319 | C8: 3032 | D8: =C8-B8 -> 713 | E8: 0.24 | F8: =IF(E8<20%,"Low",IF(E8>40%,"High","Medium")) -> Medium | G8: 55 | H8: 4.6 | I8: =IF(H8<3,"Poor",IF(H8>=4.5,"Excellent","Average")) -> Excellent
A9: Desk Foldable Fan Adjustable Fan Strong Wind 3 Gear Usb | B9: 988 | C9: 1580 | D9: =C9-B9 -> 592 | E9: 0.37 | F9: =IF(E9<20%,"Low",IF(E9>40%,"High","Medium")) -> Medium | G9: 2 | H9: 4 | I9: =IF(H9<3,"Poor",IF(H9>=4.5,"Excellent","Average")) -> Average
A10: LASA FOLDING TABLE SERVING STAND | B10: 1274 | C10: 2800 | D10: =C10-B10 -> 1526 | E10: 0.55 | F10: =IF(E10<20%,"Low",IF(E10>40%,"High","Medium")) -> High | G10: 5 | H10: 4.8 | I10: =IF(H10<3,"Poor",IF(H10>=4.5,"Excellent","Average")) -> Excellent
A11: 13 In 1 Home Repair Tools Box Kit Set | B11: 1600 | C11: 2929 | D11: =C11-B11 -> 1329 | E11: 0.45 | F11: =IF(E11<20%,"Low",IF(E11>40%,"High","Medium")) -> High | G11: 5 | H11: 3.8 | I11: =IF(H11<3,"Poor",IF(H11>=4.5,"Excellent","Average")) -> Average
A12: Genebre 115 In 1 Screwdriver Repairing Tool Set For IPhone Cellphone Hand Tool | B12: 799 | C12: 999 | D12: =C12-B12 -> 200 | E12: 0.2 | F12: =IF(E12<20%,"Low",IF(E12>40%,"High","Medium")) -> Medium | G12: 12 | H12: 4.1 | I12: =IF(H12<3,"Poor",IF(H12>=4.5,"Excellent","Average")) -> Average
A13: 100 Pcs Crochet Hook Tool Set Knitting Hook Set With Box | B13: 990 | C13: 1500 | D13: =C13-B13 -> 510 | E13: 0.34 | F13: =IF(E13<20%,"Low",IF(E13>40%,"High","Medium")) -> Medium | G13: 39 | H13: 4.7 | I13: =IF(H13<3,"Poor",IF(H13>=4.5,"Excellent","Average")) -> Excellent
... A116: Black Simple Water Cup Wine Coaster Anti Slip Absorbent | B116: 169 | C116: 320 | D116: =C116-B116 -> 151 | E116: 0.47 | F116: =IF(E116<20%,"Low",IF(E116>40%,"High","Medium")) -> High | G116: 0 | H116: 3.89 | I116: =IF(H116<3,"Poor",IF(H116>=4.5,"Excellent","Average")) -> Average
B117: =AVERAGE(B2:B116) -> 1174.3565 | C117: =AVERAGE(C2:C116) -> 1797.0696 | E117: =AVERAGE(E2:E116) -> 0.36956522 | H117: =AVERAGE(H2:H116) -> 3.8897391

Sheet Data Cleaning,Prep & Enrichment
A1: Data Cleaning & Preparation
A2: I had blanks in the rating column, so I filled them with the column's average.
A3: The review column had negatives, so I used the Find & Replace function to change the negatives to positives.
A9: Data Enrichment
A10: I created the following additional columns:
A11: Discount Amount (KSh): Old Price minus Current Price
A12: Rating Category:
A13: o Poor for ratings below 3
A14: o Average for ratings between 3 and 4.4
A15: o Excellent for ratings of 4.5 and above
A16: Discount Category:
A17: o Low Discount for discounts below 20%
... A21: You can view the outcomes on the Staging_Data Tab

Sheet Descriptive Analysis
A1: Descriptive Analysis
A2: What is the average current price, old price, discount percentage, and rating?
A3: Average Current Price | B3: =Staging_Data!B117 -> 1174.3565
A4: Average Old Price | B4: =Staging_Data!C117 -> 1797.0696
A5: Average Rating | B5: =Staging_Data!H117 -> 3.8897391
A7: Which product is the most expensive and which is the least expensive?
A8: Most Expensive | B8: =Staging_Data!A70 -> 32PCS Portable Cordless Drill Set With Cyclic Battery Drive -26 Variable Speed | C8: =Staging_Data!B70 -> 3750
A9: Least Expensive | B9: =Staging_Data!A22 -> 3PCS Single Head Knitting Crochet Sweater Needle Set | C9: =Staging_Data!B22 -> 38
A12: What is the average rating and discount by discount category?
A15: Discount Category | B15: Average of Rating | C15: Average of Discount
A16: High | B16: 3.7623077 | C16: 0.48123077
A17: Low | B17: 3.8533333 | C17: 0.072222222
A18: Medium | B18: 4.1690625 | C18: 0.31
A19: Grand Total | B19: 3.8897391 | C19: 0.36956522
A21: How are products distributed across rating categories?
A23: Rating Category | B23: Count of Product
A24: Average | B24: 80
A25: Excellent | B25: 23
A26: Poor | B26: 12
A27: Grand Total | B27: 115
A35: Discount Category | B35: Count of Product
A36: High | B36: 65
A37: Low | B37: 18
A38: Medium | B38: 32
A39: Grand Total | B39: 115

Sheet Trend & Relationship Analysis
A1: The relationship between discount percentage and number of reviews
A2: Discount Category | B2: Sum of Review
A3: High | B3: 334
A4: Low | B4: 38
A5: Medium | B5: 351
A6: Grand Total | B6: 723 | K6: High discounts does not lead to a high number of reviews.
A15: The relationship between rating and number of reviews
A16: Rating Category | B16: Sum of Review
A17: Average | B17: 223
A18: Excellent | B18: 331
A19: Poor | B19: 169 | K19: An excellent rating has more number of reviews
A20: Grand Total | B20: 723
A29: Whether higher discounts lead to increased customer engagement. YES
A30: Whether higher-rated products tend to have more reviews. NO

Sheet Product Perfomance Analysis
A1: The top 10 products with the highest discounts
A3: Row Labels | B3: Max of Discount
A4: 6 In 1 Bottle Can Opener Multifunctional Easy Opener | B4: 0.64
A5: Creative Owl Shape Keychain Black | B5: 0.61
A6: 5-PCS Stainless Steel Cooking Pot Set With Steamed Slices | B6: 0.55
A7: LASA FOLDING TABLE SERVING STAND | B7: 0.55
A8: Simple Metal Dog Art Sculpture Decoration For Home Office | B8: 0.55
A9: Mythco 120COB Solar Wall Ligt With Motion Sensor And Remote Control 3 Modes | B9: 0.54
A10: LASA 3 Tier Bamboo Shoe Bench Storage Shelf | B10: 0.54
A11: Classic Black Cat Cotton Hemp Pillow Case For Home Car | B11: 0.53
A12: 3PCS Single Head Knitting Crochet Sweater Needle Set | B12: 0.53
A13: Intelligent LED Body Sensor Wireless Lighting Night Light USB | B13: 0.52
A14: Exfoliate And Exfoliate Face Towel - Black | B14: 0.52
A15: Grand Total | B15: 0.64
A17: The top 10 products with the most reviews
A19: Row Labels | B19: Max of Review
A20: 120W Cordless Vacuum Cleaners Handheld Electric Vacuum Cleaner | B20: 69
A21: 137 Pieces Cake Decorating Tool Set Baking Supplies | B21: 55
A22: Electronic Digital Display Vernier Caliper | B22: 49
A23: 3D Waterproof EVA Plastic Shower Curtain 1.8*2Mtrs | B23: 44
A24: 100 Pcs Crochet Hook Tool Set Knitting Hook Set With Box | B24: 39
A25: Punch-free Great Load Bearing Bathroom Storage Rack Wall Shelf-White | B25: 36
A26: 53 Pieces/Set Yarn Knitting Crochet Hooks With Bag - Pansies | B26: 32
A27: Portable Mini Cordless Car Vacuum Cleaner - Blue | B27: 24
A28: 53Pcs/Set Yarn Knitting Crochet Hooks With Bag - Fortune Cat | B28: 20
A29: 52 Pieces Cake Decorating Tool Set Gift Kit Baking Supplies | B29: 20
A30: Grand Total | B30: 69
A32: The top 5 highest-rated and bottom 5 lowest-rated products
A33: Top 5 High-rated Products
A34: Row Labels | B34: Max of Rating
A35: Anti-Skid Absorbent Insulation Coaster For Home Office | B35: 5
A36: Bedroom Simple Floor Hanging Clothes Rack Single Pole Hat Rack - White | B36: 5
A37: Classic Black Cat Cotton Hemp Pillow Case For Home Car | B37: 5
A38: DIY File Folder, Office Drawer File Holder, Pen Holder, Desktop Storage Rack | B38: 5
A39: Konka Healty Electric Kettle, 24-hour Heat Preservation,1.5L,800W, White | B39: 5
A40: LASA Aluminum Folding Truck Hand Cart - 68kg Max | B40: 5
A41: Peacock Throw Pillow Cushion Case For Home Car | B41: 5
A42: Grand Total | B42: 5
A47: Bottom 5 Lowest-rated Products
A48: Row Labels | B48: Min of Rating
...

Sheet Dashboard
